<?xml version="1.0"?>
<robot name="testbot">
  <link name="body">
    <visual>
      <geometry>
        <box size="1 0.7 0.4" />
      </geometry>
      <origin xyz="0 0 0" rpy="0 0 0" />
      <material name="default_material">
        <color rgba="0.8 0.8 0.8 1.0" />
      </material>
    </visual>
    <collision>
      <geometry>
        <box size="1 0.7 0.4" />
      </geometry>
      <origin xyz="0 0 0" rpy="0 0 0" />
    </collision>
    <inertial>
      <mass value="10" />
      <origin xyz="0 0 0" rpy="0 0 0" />
      <inertia ixx="0.5416666666666666" ixy="0" ixz="0" iyy="0.9666666666666668" iyz="0" izz="1.2416666666666667" />
    </inertial>
  </link>
  <link name="arm1">
    <visual>
      <geometry>
        <box size="0.5 0.2 0.1" />
      </geometry>
      <origin xyz="0.27 0.0 0.0" rpy="0 0 0" />
      <material name="default_material">
        <color rgba="0.8 0.8 0.8 1.0" />
      </material>
    </visual>
    <collision>
      <geometry>
        <box size="0.5 0.2 0.1" />
      </geometry>
      <origin xyz="0.27 0.0 0.0" rpy="0 0 0" />
    </collision>
    <inertial>
      <mass value="2" />
      <origin xyz="0.27 0.0 0.0" rpy="0 0 0" />
      <inertia ixx="0.008333333333333335" ixy="0" ixz="0" iyy="0.043333333333333335" iyz="0" izz="0.04833333333333334" />
    </inertial>
  </link>
  <joint name="shoulder1" type="revolute">
    <parent link="body" />
    <child link="arm1" />
    <axis xyz="0 1 0" />
    <limit lower="-2.199114857512855" upper="2.199114857512855" effort="1000.0" velocity="1.0" />
    <origin xyz="0.5 0 0" rpy="0 0 0" />
  </joint>
</robot>
